/**
 * Test stability and retry logic tests
 */
import { describe, it, expect, vi, beforeEach } from 'vitest';

describe('Test Stability', () => {
  describe('Async Handling', () => {
    it('should handle async operations with proper awaits', async () => {
      const asyncOperation = vi.fn().mockResolvedValue('success');
      
      const result = await asyncOperation();
      
      expect(result).toBe('success');
      expect(asyncOperation).toHaveBeenCalledTimes(1);
    });

    it('should handle rejected promises gracefully', async () => {
      const failingOperation = vi.fn().mockRejectedValue(new Error('Operation failed'));
      
      await expect(failingOperation()).rejects.toThrow('Operation failed');
      expect(failingOperation).toHaveBeenCalledTimes(1);
    });

    it('should handle race conditions with Promise.all', async () => {
      const operations = [
        vi.fn().mockResolvedValue('result1'),
        vi.fn().mockResolvedValue('result2'),
        vi.fn().mockResolvedValue('result3')
      ];

      const results = await Promise.all(operations.map(op => op()));
      
      expect(results).toEqual(['result1', 'result2', 'result3']);
      operations.forEach(op => expect(op).toHaveBeenCalledTimes(1));
    });
  });

  describe('Retry Logic', () => {
    const createRetryableFunction = (maxAttempts: number = 3, delay: number = 100) => {
      return async <T>(fn: () => Promise<T>): Promise<T> => {
        let lastError: Error;
        
        for (let attempt = 1; attempt <= maxAttempts; attempt++) {
          try {
            return await fn();
          } catch (error) {
            lastError = error as Error;
            
            if (attempt === maxAttempts) {
              throw lastError;
            }
            
            // Wait before retrying
            await new Promise(resolve => setTimeout(resolve, delay * attempt));
          }
        }
        
        throw lastError!;
      };
    };

    it('should retry failed operations up to max attempts', async () => {
      const retry = createRetryableFunction(3, 10);
      const failingOperation = vi.fn()
        .mockRejectedValueOnce(new Error('Attempt 1 failed'))
        .mockRejectedValueOnce(new Error('Attempt 2 failed'))
        .mockResolvedValueOnce('Success on attempt 3');

      const result = await retry(() => failingOperation());
      
      expect(result).toBe('Success on attempt 3');
      expect(failingOperation).toHaveBeenCalledTimes(3);
    });

    it('should fail after max attempts are exhausted', async () => {
      const retry = createRetryableFunction(2, 10);
      const alwaysFailingOperation = vi.fn()
        .mockRejectedValue(new Error('Always fails'));

      await expect(retry(() => alwaysFailingOperation())).rejects.toThrow('Always fails');
      expect(alwaysFailingOperation).toHaveBeenCalledTimes(2);
    });

    it('should succeed immediately if first attempt works', async () => {
      const retry = createRetryableFunction(3, 10);
      const successfulOperation = vi.fn().mockResolvedValue('Immediate success');

      const result = await retry(() => successfulOperation());
      
      expect(result).toBe('Immediate success');
      expect(successfulOperation).toHaveBeenCalledTimes(1);
    });
  });

  describe('Test Isolation', () => {
    it('should not affect other tests with side effects', () => {
      const globalState = { count: 0 };
      
      // Test operation
      globalState.count += 1;
      expect(globalState.count).toBe(1);
      
      // Reset state for isolation
      globalState.count = 0;
      expect(globalState.count).toBe(0);
    });

    it('should clean up mocks properly', () => {
      const mockFn = vi.fn();
      mockFn('test');
      
      expect(mockFn).toHaveBeenCalledWith('test');
      
      // Clean up
      mockFn.mockReset();
      expect(mockFn).toHaveBeenCalledTimes(0);
    });
  });

  describe('Timing-Dependent Tests', () => {
    it('should handle timing with fake timers', async () => {
      vi.useFakeTimers();
      
      const callback = vi.fn();
      setTimeout(callback, 1000);
      
      // Fast-forward time
      vi.advanceTimersByTime(1000);
      
      expect(callback).toHaveBeenCalledTimes(1);
      
      vi.useRealTimers();
    });

    it('should test debounced functions', async () => {
      vi.useFakeTimers();
      
      const debounce = (fn: Function, delay: number) => {
        let timeoutId: NodeJS.Timeout;
        return (...args: any[]) => {
          clearTimeout(timeoutId);
          timeoutId = setTimeout(() => fn(...args), delay);
        };
      };
      
      const originalFn = vi.fn();
      const debouncedFn = debounce(originalFn, 200);
      
      // Call multiple times rapidly
      debouncedFn('call1');
      debouncedFn('call2');
      debouncedFn('call3');
      
      // Should not have been called yet
      expect(originalFn).toHaveBeenCalledTimes(0);
      
      // Fast-forward past debounce delay
      vi.advanceTimersByTime(200);
      
      // Should have been called only once with the last argument
      expect(originalFn).toHaveBeenCalledTimes(1);
      expect(originalFn).toHaveBeenCalledWith('call3');
      
      vi.useRealTimers();
    });
  });

  describe('Error Recovery', () => {
    it('should handle network errors gracefully', async () => {
      const networkCall = vi.fn()
        .mockRejectedValueOnce(new Error('ECONNREFUSED'))
        .mockResolvedValueOnce({ data: 'success' });

      // Simulate retry on network error
      let result;
      try {
        result = await networkCall();
      } catch (error) {
        // Retry on network error
        result = await networkCall();
      }
      
      expect(result).toEqual({ data: 'success' });
      expect(networkCall).toHaveBeenCalledTimes(2);
    });

    it('should handle timeout scenarios', async () => {
      const longRunningOperation = () => new Promise((resolve) => {
        setTimeout(() => resolve('completed'), 5000);
      });

      const timeoutPromise = new Promise((_, reject) => {
        setTimeout(() => reject(new Error('Operation timed out')), 1000);
      });

      await expect(
        Promise.race([longRunningOperation(), timeoutPromise])
      ).rejects.toThrow('Operation timed out');
    });
  });
});